Workbook
Name __xlfn_IFERROR: #N/A
Name AnchorCell: #REF!
Name ProductID: #REF!

Sheet Home Ext
C5: Halooo… Sahabat Referral | E5: Karyawan Internal | I5: Dana Tunai | O5: Pembiayaan Mobil Bekas | U5: Kelengkapan Dokumen & Tracking Aplikasi | AC5: Pembiayaan Emas / Logam Mulia | AI5: Pembiayaan Mobil Baru
E7: Karyawan Authorized Dealer | I7: Type Debitur | O7: Type Debitur | AC7: Type Debitur | AI7: Type Debitur
E9: Karyawan Perbankan | I9: Perorangan (Wiraswasta) | O9: Perorangan (Wiraswasta) | U9: Kode Referral | AC9: Perorangan | AI9: Perorangan
E11: Karyawan Asuransi Rekanan | I11: Jika Debitur Perorangan, usia saat ini | O11: Jika Debitur Perorangan, usia saat ini | U11: 9anxfq | AC11: Jika Debitur Perorangan, usia saat ini | AI11: Jika Debitur Perorangan, usia saat ini
E13: Agent Retail | I13: 36-45 tahun | O13: 36-45 tahun | U13: Nama Debitur | AC13: 36-45 tahun | AI13: 36-45 tahun
E15: Showroom Mobil Bekas | I15: =IF($C$95="Pembiayaan Emas / Logam Mulia","","Type Kendaraan") -> Type Kendaraan | O15: =IF($C$95="Pembiayaan Emas / Logam Mulia","","Type Kendaraan") -> Type Kendaraan | U15: =VLOOKUP($U$11,'Data in out'!$B$24:$AL$323,2,0) -> AAAAAA | AC15: =IF($C$95="Pembiayaan Emas / Logam Mulia","","Type Kendaraan") -> Type Kendaraan | AI15: =IF($C$95="Pembiayaan Emas / Logam Mulia","","Type Kendaraan") -> Type Kendaraan
I17: Passenger | O17: Commercial | U17: Nama AO | AC17: Passenger | AI17: Passenger
I19: =IF(C95="Pembiayaan Emas / Logam Mulia","","Merk Kendaraan") -> Merk Kendaraan | O19: =IF(I95="Pembiayaan Emas / Logam Mulia","","Merk Kendaraan") -> Merk Kendaraan | U19: =VLOOKUP($U$11,'Data in out'!$B$24:$AL$323,3,0) -> Ade | AC19: =IF(W75="Pembiayaan Emas / Logam Mulia","","Merk Kendaraan") -> Merk Kendaraan | AI19: =IF(AC75="Pembiayaan Emas / Logam Mulia","","Merk Kendaraan") -> Merk Kendaraan
C21: Butuh Dana Tunai untuk? dan Kebutuhan? | E21: Pendidikan | I21: HONDA | O21: HONDA | U21: Type Debitur | AC21: HONDA | AI21: HONDA
E23: Modal Usaha | I23: Type Kendaraan | O23: Type Kendaraan | U23: =VLOOKUP($U$11,'Data in out'!$B$24:$AL$323,6,0) -> Perorangan (Non Wiraswasta) | AC23: Type Kendaraan | AI23: Type Kendaraan
E25: Renovasi Rumah | I25: BRIO | O25: BRIO | U25: =IF($U$23="Badan Hukum Usaha"," ","Konfirmasi Sumber Penghasilan lainnya") -> Konfirmasi Sumber Penghasilan lainnya | AC25: BRIO | AI25: BRIO
C27: Debitur/ Nasabah, dengan jaminan BPKB Mobil | E27: Liburan / Wisata Religi | I27: Model Kendaraan | O27: Model Kendaraan | U27: =VLOOKUP($U$11,'Data in out'!$B$24:$AL$323,7,0) -> Pasangan Bekerja dan memiliki penghasilan | AC27: Model Kendaraan | AI27: Model Kendaraan
E29: Pernikahan / Persalinan | I29: ALL NEW BRIO RS CVT | O29: ALL NEW BRIO RS CVT | AC29: ALL NEW BRIO RS CVT | AI29: ALL NEW BRIO RS CVT
I31: Tahun Kendaraan | K31: Type Angsuran | O31: Tahun Kendaraan | Q31: Type Angsuran | AC31: Tahun Kendaraan | AI31: Tahun Kendaraan
C33: Cara Mudah Mendapatkan Simulasi Pembiayaan & | D33: Cara Mudah Mengajukan Pinjaman | E33: Cara Mudah Mengajukan Pinjaman | I33: 2020 | K33: ADDB | O33: 2015 | Q33: ADDB | AC33: 2017 | AI33: 2017
C35: Tracking Proses Permohonan Pembiayaan Realtime | I35: Asuransi | O35: Asuransi | U35: Kelengkapan Dokumen Permohonan Pembiayaan
I37: Comprehensive 1 tahun | O37: TLO All Tenor | U37: 1 | W37: =IF($U$23="Badan Hukum Usaha","KTP Komisaris","KTP Pemohon") -> KTP Pemohon | Y37: =Z37 -> 2 | Z37: =VLOOKUP($U$15,'Data in out'!$C$24:$BQ$323,7,0) -> 2
D39: 1 | E39: Registrasi | U39: 2 | W39: =IF($U$23="Badan Hukum Usaha","KTP Direksi","KTP Pasangan") -> KTP Pasangan | Y39: =Z39 -> 2 | Z39: =VLOOKUP($U$15,'Data in out'!$C$24:$BQ$323,8,0) -> 2
I41: Simulasi Dana Tunai | O41: Simulasi Pembiayaan Mobil Bekas | U41: 3 | W41: =IF($U$23="Badan Hukum Usaha","NPWP Direksi","NPWP Pemohon") -> NPWP Pemohon | Y41: =Z41 -> 2 | Z41: =VLOOKUP($U$15,'Data in out'!$C$24:$BQ$323,9,0) -> 2
I43: STNK atas nama | U43: 4 | W43: =IF($U$23="Badan Hukum Usaha","NPWP Usaha","Kartu Keluarga") -> Kartu Keluarga | Y43: =Z43 -> 2 | Z43: =VLOOKUP($U$15,'Data in out'!$C$24:$BQ$323,10,0) -> 2 | AC43: STNK atas nama | AI43: STNK atas nama
I45: Pribadi (milik sendiri) | U45: 5 | W45: =IF($U$23="Badan Hukum Usaha","Akte Pendirian","Bukti Kepemilikan Rumah (SPPT PBB/AJB/SHM") -> Bukti Kepemilikan Rumah (SPPT PBB/AJB/SHM | Y45: =Z45 -> 2 | Z45: =VLOOKUP($U$15,'Data in out'!$C$24:$BQ$323,11,0) -> 2 | AC45: Pribadi (milik sendiri) | AI45: Pribadi (milik sendiri)
D47: 2 | E47: Isi Form Online | I47: Harga Taksasi | O47: Harga Pasar | U47: 6 | W47: =IF($U$23="Badan Hukum Usaha","Akte Perubahan","Rek Koran 3 bulan terakhir") -> Rek Koran 3 bulan terakhir | Y47: 1 | Z47: =VLOOKUP($U$15,'Data in out'!$C$24:$BQ$323,12,0) -> 2 | AC47: Harga OTR | AI47: Harga OTR
I49: =ROUNDDOWN(VLOOKUP('DT Ext'!$B$10,'PHPM 1 DT Ext'!$K$5:$L$841,2,0),-2) -> 140000000 | O49: 110000000 | U49: 7 | W49: =IF($U$23="Perorangan (Wiraswasta)","Legalitas Usaha (NIB/SKDU)",IF($U$23="Perorangan (Non Wiraswasta)","Slip Gaji Carbonized","SK Kemenkumham")) -> Slip Gaji Carbonized | Y49: 1 | Z49: =VLOOKUP($U$15,'Data in out'!$C$24:$BQ$323,13,0) -> 2 | AC49: ='DT Ext'!$F$13 -> 140000000 | AI49: ='DT Ext'!$F$13 -> 140000000
I51: Pencairan Maksimal | K51: Angsuran perbulan | O51: Pencairan All In | Q51: Angsuran perbulan | U51: =IF(W51=" "," ",8) | W51: =IF($U$23="Perorangan (Wiraswasta)","Bon / Faktur Penjualan",IF($U$23="Perorangan (Non Wiraswasta)"," ","Legalitas Usaha (NIB & Ijin Usaha khusus)")) | Y51: =Z51 -> 0 | Z51: =IF(W51=" ",0,VLOOKUP($U$15,'Data in out'!$C$24:$BQ$323,14,0)) -> 0 | AC51: Pencairan Maksimal | AE51: Angsuran perbulan | AI51: Pencairan Maksimal | AK51: Angsuran perbulan
I53: ='DT Ext'!$E$73 -> 122059100 | J53: =_xlfn.UNICHAR(9312) -> ① | K53: ='DT Ext'!$G$73 -> 11926000 | O53: ='UC Ext'!$E$78 -> 0 | P53: =_xlfn.UNICHAR(9312) -> ① | Q53: ='UC Ext'!$G$78 -> 0 | U53: =IF(W53=" "," ",9) | W53: =IF($U$23="Perorangan (Wiraswasta)","Surat Ijin Profesi (khusus untuk tenaga profesional)",IF($U$23="Perorangan (Non Wiraswasta)"," ","Laporan Keuangan")) | Y53: =Z53 -> 0 | Z53: =IF(W53=" ",0,VLOOKUP($U$15,'Data in out'!$C$24:$BQ$323,15,0)) -> 0 | AC53: ='DT Ext'!$E$73 -> 122059100 | AD53: =_xlfn.UNICHAR(9312) -> ① | AE53: ='DT Ext'!$G$73 -> 11926000 | AI53: ='DT Ext'!$E$73 -> 122059100 | AJ53: =_xlfn.UNICHAR(9312) -> ① | AK53: ='DT Ext'!$G$73 -> 11926000
D55: 3 | E55: Ajukan sesuai kebutuhan Debitur anda | I55: ='DT Ext'!$E$74 -> 120594700 | J55: =_xlfn.UNICHAR(9313) -> ② | K55: ='DT Ext'!$G$74 -> 6352000 | O55: ='UC Ext'!$E$79 -> 0 | P55: =_xlfn.UNICHAR(9313) -> ② | Q55: ='UC Ext'!$G$79 -> 0 | U55: =IF(W55=" "," ",10) | W55: =IF($U$23="Perorangan (Wiraswasta)"," ",IF($U$23="Perorangan (Non Wiraswasta)"," ","Rek Koran 3 Bulan terakhir")) | Y55: =Z55 -> 0 | Z55: =IF(W55=" ",0,VLOOKUP($U$15,'Data in out'!$C$24:$BQ$323,16,0)) -> 0 | AC55: ='DT Ext'!$E$74 -> 120594700 | AD55: =_xlfn.UNICHAR(9313) -> ② | AE55: ='DT Ext'!$G$74 -> 6352000 | AI55: ='DT Ext'!$E$74 -> 120594700 | AJ55: =_xlfn.UNICHAR(9313) -> ② | AK55: ='DT Ext'!$G$74 -> 6352000
I57: ='DT Ext'!$E$75 -> 118902100 | J57: =_xlfn.UNICHAR(9314) -> ③ | K57: ='DT Ext'!$G$75 -> 4514000 | O57: ='UC Ext'!$E$80 -> 0 | P57: =_xlfn.UNICHAR(9314) -> ③ | Q57: ='UC Ext'!$G$80 -> 0 | U57: =IF(W57=" "," ",11) | W57: =IF($U$23="Perorangan (Wiraswasta)"," ",IF($U$23="Perorangan (Non Wiraswasta)"," ","SPK /MOU")) | Y57: =Z57 -> 0 | Z57: =IF(W57=" ",0,VLOOKUP($U$15,'Data in out'!$C$24:$BQ$323,17,0)) -> 0 | AC57: ='DT Ext'!$E$75 -> 118902100 | AD57: =_xlfn.UNICHAR(9314) -> ③ | AE57: ='DT Ext'!$G$75 -> 4514000 | AI57: ='DT Ext'!$E$75 -> 118902100 | AJ57: =_xlfn.UNICHAR(9314) -> ③ | AK57: ='DT Ext'!$G$75 -> 4514000
I59: ='DT Ext'!$E$76 -> 116972900 | J59: =_xlfn.UNICHAR(9315) -> ④ | K59: ='DT Ext'!$G$76 -> 3700000 | O59: ='UC Ext'!$E$81 -> 0 | P59: =_xlfn.UNICHAR(9315) -> ④ | Q59: ='UC Ext'!$G$81 -> 0 | AC59: ='DT Ext'!$E$76 -> 116972900 | AD59: =_xlfn.UNICHAR(9315) -> ④ | AE59: ='DT Ext'!$G$76 -> 3700000 | AI59: ='DT Ext'!$E$76 -> 116972900 | AJ59: =_xlfn.UNICHAR(9315) -> ④ | AK59: ='DT Ext'!$G$76 -> 3700000
C61: Bosan dengan mobil anda, atau mau ganti yang lebih muda? | I61: ='DT Ext'!$E$77 -> 115171100 | J61: =_xlfn.UNICHAR(9316) -> ⑤ | K61: ='DT Ext'!$G$77 -> 3227000 | O61: ='UC Ext'!$E$82 -> 0 | P61: =_xlfn.UNICHAR(9316) -> ⑤ | Q61: ='UC Ext'!$G$82 -> 0 | AC61: ='DT Ext'!$E$77 -> 115171100 | AD61: =_xlfn.UNICHAR(9316) -> ⑤ | AE61: ='DT Ext'!$G$77 -> 3227000 | AI61: ='DT Ext'!$E$77 -> 115171100 | AJ61: =_xlfn.UNICHAR(9316) -> ⑤ | AK61: ='DT Ext'!$G$77 -> 3227000
C63: Atau ganti dengan Mobil Baru? | I63: Nominal pembiayaan bersifat Estimasi | O63: Nominal pembiayaan bersifat Estimasi | U63: =IF($U$23="Badan Hukum Usaha"," ",IF($U$27="Tidak Ada"," ",$U$27)) -> Pasangan Bekerja dan memiliki penghasilan | AC63: Nominal pembiayaan bersifat Estimasi | AI63: Nominal pembiayaan bersifat Estimasi
C65: Atau mau lengkapi koleksi Logam Mulia anda, dengan cara mudah | I65: Besarnya pembiayaan berdasarkan hasil | O65: Besarnya pembiayaan berdasarkan hasil | U65: =IF($U$23="Badan Hukum Usaha"," ",IF($U$27="Tidak Ada"," ",1)) -> 1 | W65: =IF($U$23="Badan Hukum Usaha"," ",IF($U$27="Tidak Ada"," ","Rek Koran 3 bulan terakhir")) -> Rek Koran 3 bulan terakhir | Y65: =Z65 -> 2 | Z65: =IF(W65=" ",0,VLOOKUP($U$15,'Data in out'!$C$24:$BQ$323,18,0)) -> 2 | AC65: Besarnya pembiayaan berdasarkan hasil | AI65: Besarnya pembiayaan berdasarkan hasil
C67: Kami hadir Mewujudkan mimpi anda, sekarang | I67: Verifikasi Profil Debitur dan kondisi Kendaraan | O67: Verifikasi Profil Debitur dan kondisi Kendaraan | U67: =IF($U$23="Badan Hukum Usaha"," ",IF($U$27="Tidak Ada"," ",2)) -> 2 | W67: =IF($U$23="Badan Hukum Usaha"," ",IF($U$27="Pasangan Bekerja dan memiliki penghasilan","Slip Gaji Carbonized",IF($U$27="Pasangan memiliki usaha lainnya dan memiliki penghasilan","Legalitas Usaha (NIB/SKDU)",IF($U$27="Pasangan adalah profesional dan memiliki penghasilan","Surat Ijin Profesi"," ")))) -> Slip Gaji Carbonized | Y67: =Z67 -> 2 | Z67: =IF(W67=" ",0,VLOOKUP($U$15,'Data in out'!$C$24:$BQ$323,19,0)) -> 2 | AC67: Verifikasi Profil Debitur dan kondisi Kendaraan | AI67: Verifikasi Profil Debitur dan kondisi Kendaraan
C69: menawarkan Solusi Cepat dan Mudah | I69: AJUKAN | O69: AJUKAN | U69: =IF(OR($U$23="Perorangan (Wiraswasta)",$W$69="Bon / Faktur Penjualan"),3," ") | W69: =IF($U$23="Badan Hukum Usaha"," ",IF($U$27="Pasangan Bekerja dan memiliki penghasilan"," ",IF($U$27="Pasangan memiliki usaha lainnya dan memiliki penghasilan","Bon / Faktur Penjualan",IF($U$27="Pasangan adalah profesional dan memiliki penghasilan"," "," ")))) | Y69: =Z69 -> 0 | Z69: =IF(W69=" ",0,VLOOKUP($U$15,'Data in out'!$C$24:$BQ$323,20,0)) -> 0 | AC69: AJUKAN | AI69: AJUKAN
C73: NAMA LENGKAP | I73: Dana yang dibutuhkan | O73: Total DP Dikehendaki | AC73: Dana yang dibutuhkan | AI73: Dana yang dibutuhkan
I75: 60000000 | O75: 60000000 | U75: Tracking Aplikasi | AC75: 60000000 | AI75: 60000000
C77: TGL LAHIR | I77: Hitung | O77: Hitung | U77: 1 | W77: Verifikasi, Validasi dan kelengkapan data permohonan | Y77: =Z77 -> 2 | Z77: =IF(W77=" ",0,VLOOKUP($U$15,'Data in out'!$C$24:$BQ$323,21+U77,0)) -> 2 | AC77: Hitung | AI77: Hitung
C79: DD/MM/YYYY | J79: =_xlfn.UNICHAR(9312) -> ① | K79: ='DT Ext'!$G$69 -> 6361000 | P79: =_xlfn.UNICHAR(9312) -> ① | Q79: ='UC Ext'!$O$78 -> 0 | U79: 2 | W79: Survey Domisili & Tempat usaha/Kantor | Y79: =Z79 -> 2 | Z79: =IF(W79=" ",0,VLOOKUP($U$15,'Data in out'!$C$24:$BQ$323,21+U79,0)) -> 2 | AD79: =_xlfn.UNICHAR(9312) -> ① | AE79: ='DT Ext'!$G$69 -> 6361000 | AJ79: =_xlfn.UNICHAR(9312) -> ① | AK79: ='DT Ext'!$G$69 -> 6361000
C81: ALAMAT EMAIL | J81: =_xlfn.UNICHAR(9313) -> ② | K81: ='DT Ext'!$O$74 -> 3458000 | P81: =_xlfn.UNICHAR(9313) -> ② | Q81: ='UC Ext'!$O$79 -> 0 | U81: 3 | W81: Cek fisik Kendaraan | Y81: =Z81 -> 2 | Z81: =IF(W81=" ",0,VLOOKUP($U$15,'Data in out'!$C$24:$BQ$323,21+U81,0)) -> 2 | AD81: =_xlfn.UNICHAR(9313) -> ② | AE81: ='DT Ext'!$O$74 -> 3458000 | AJ81: =_xlfn.UNICHAR(9313) -> ② | AK81: ='DT Ext'!$O$74 -> 3458000
J83: =_xlfn.UNICHAR(9314) -> ③ | K83: ='DT Ext'!$O$75 -> 2515000 | P83: =_xlfn.UNICHAR(9314) -> ③ | Q83: ='UC Ext'!$O$80 -> 0 | U83: 4 | W83: Laporan Hasil Survey. | Y83: =Z83 -> 2 | Z83: =IF(W83=" ",0,VLOOKUP($U$15,'Data in out'!$C$24:$BQ$323,21+U83,0)) -> 2 | AD83: =_xlfn.UNICHAR(9314) -> ③ | AE83: ='DT Ext'!$O$75 -> 2515000 | AJ83: =_xlfn.UNICHAR(9314) -> ③ | AK83: ='DT Ext'!$O$75 -> 2515000
C85: No. HAND PHONE | J85: =_xlfn.UNICHAR(9315) -> ④ | K85: ='DT Ext'!$O$76 -> 2115000 | P85: =_xlfn.UNICHAR(9315) -> ④ | Q85: ='UC Ext'!$O$81 -> 0 | U85: 5 | W85: Proses Aplikasi | Y85: =Z85 -> 2 | Z85: =IF(W85=" ",0,VLOOKUP($U$15,'Data in out'!$C$24:$BQ$323,21+U85,0)) -> 2 | AD85: =_xlfn.UNICHAR(9315) -> ④ | AE85: ='DT Ext'!$O$76 -> 2115000 | AJ85: =_xlfn.UNICHAR(9315) -> ④ | AK85: ='DT Ext'!$O$76 -> 2115000
...

Sheet DT Ext
B4: Merk | D4: ='Home Ext'!$I$21 -> HONDA | G4: Type Kendaraan | I4: ='Home Ext'!$I$25 -> BRIO | N4: Deposit Angsuran | P4: 0 | Q4: Up ACP | S4: 0.3
B5: Type Debitur | D5: ='Home Ext'!$I$9 -> Perorangan (Wiraswasta) | G5: Model Kendaraan | I5: ='Home Ext'!$I$29 -> ALL NEW BRIO RS CVT | N5: BBNKB | O5: 0 | Q5: Up Rate | S5: 0
B6: Type Angsuran | D6: ADDB | G6: Penggunaan Unit | I6: ='Home Ext'!$I$17 -> Passenger | N6: PKB | O6: 0 | Q6: Up Adm | S6: 0
B7: Type Unit | D7: =VLOOKUP('Home Ext'!$I$21,'PHPM 2 DT Ext'!$D$4:$E$55,2,0) -> Japan | G7: Product | I7: =CONCATENATE(VLOOKUP('Home Ext'!$C$91,'Data Ext'!$C$5:$F$11,2,0)," ",'Home Ext'!$I$17," ",VLOOKUP('Home Ext'!$C$91,'Data Ext'!$C$5:$F$11,4,0)) -> Captive Passenger Khusus SME & Private/Prioritas | N7: FAKTUR | O7: 0 | Q7: Up Provisi | S7: 0
B8: Thn (NIK) | D8: ='Home Ext'!$I$33 -> 2020 | F8: =15-(2026-D8) -> 9 | G8: Asuransi | I8: Comprehensive 1 tahun, sisanya TLO | N8: Asuransi | O8: BATAS BAWAH | Q8: Usia Debitur | S8: ='Home Ext'!$I$13 -> 36-45 tahun
B9: TENOR | F9: 1 | G9: =F9*12 -> 12 | I9: 2 | J9: =I9*12 -> 24 | L9: 3 | M9: =L9*12 -> 36 | O9: 4 | P9: =O9*12 -> 48 | R9: 5 | S9: =R9*12 -> 60
B10: =CONCATENATE('Home Ext'!$I$21,"-",'Home Ext'!$I$25,"-",'Home Ext'!$I$29) -> HONDA-BRIO-ALL NEW BRIO RS CVT | F10: =(16-F9)-(2026-$D$8) -> 9 | I10: =(16-I9)-(2026-$D$8) -> 8 | L10: =(16-L9)-(2026-$D$8) -> 7 | O10: =(16-O9)-(2026-$D$8) -> 6 | R10: =(16-R9)-(2026-$D$8) -> 5
B11: Harga OTR | D11: PASAR | F11: =F13 -> 140000000 | I11: =I13 -> 140000000 | L11: =L13 -> 140000000 | O11: =O13 -> 140000000 | R11: =R13 -> 140000000
D12: PHPM | F12: =IF(F10>=1,VLOOKUP($B$10,'PHPM 1 DT Ext'!$K$5:$L$841,2,0),0) -> 140000016 | I12: =IF(I10>=1,VLOOKUP($B$10,'PHPM 1 DT Ext'!$K$5:$L$841,2,0),0) -> 140000016 | L12: =IF(L10>=1,VLOOKUP($B$10,'PHPM 1 DT Ext'!$K$5:$L$841,2,0),0) -> 140000016 | O12: =IF(O10>=1,VLOOKUP($B$10,'PHPM 1 DT Ext'!$K$5:$L$841,2,0),0) -> 140000016 | R12: =IF(R10>=1,VLOOKUP($B$10,'PHPM 1 DT Ext'!$K$5:$L$841,2,0),0) -> 140000016
D13: ROUNDDOWN PHPM | F13: =ROUNDDOWN(F12,-2) -> 140000000 | I13: =ROUNDDOWN(I12,-2) -> 140000000 | L13: =ROUNDDOWN(L12,-2) -> 140000000 | O13: =ROUNDDOWN(O12,-2) -> 140000000 | R13: =ROUNDDOWN(R12,-2) -> 140000000
B14: Deviasi (%) | D14: (Rp.) | F14: =IFERROR(G14/F11,0) -> 0 | G14: =IF(F11<=F12,0,F11-F12) -> 0 | I14: =IFERROR(J14/I11,0) -> 0 | J14: =IF(I11<=I12,0,I11-I12) -> 0 | L14: =IFERROR(M14/L11,0) -> 0 | M14: =IF(L11<=L12,0,L11-L12) -> 0 | O14: =IFERROR(P14/O11,0) -> 0 | P14: =IF(O11<=O12,0,O11-O12) -> 0 | R14: =IFERROR(S14/R11,0) -> 0 | S14: =IF(R11<=R12,0,R11-R12) -> 0
B15: Sum Insured | D15: % | E15: Rp. | F15: 1 | G15: =F11*F15 -> 140000000 | I15: 0.9 | J15: =I11*I15 -> 126000000 | L15: 0.8 | M15: =L11*L15 -> 112000000 | O15: 0.7 | P15: =O11*O15 -> 98000000 | R15: 0.7 | S15: =R11*R15 -> 98000000
B16: Net DP | D16: % | E16: Rp. | F16: =IF('Home Ext'!$I$45="Orang lain",15%,IF(OR($I$6="Commercial",$D$7="Non Japan"),15%,5%)) -> 0.05 | G16: =F11*F16 -> 7000000 | I16: =IF('Home Ext'!$I$45="Orang lain",15%,IF(OR($I$6="Commercial",$D$7="Non Japan"),15%,5%)) -> 0.05 | J16: =I11*I16 -> 7000000 | L16: =IF('Home Ext'!$I$45="Orang lain",15%,IF(OR($I$6="Commercial",$D$7="Non Japan"),15%,5%)) -> 0.05 | M16: =L11*L16 -> 7000000 | O16: =IF('Home Ext'!$I$45="Orang lain",15%,IF(OR($I$6="Commercial",$D$7="Non Japan"),15%,5%)) -> 0.05 | P16: =O11*O16 -> 7000000 | R16: =IF('Home Ext'!$I$45="Orang lain",15%,IF(OR($I$6="Commercial",$D$7="Non Japan"),15%,5%)) -> 0.05 | S16: =R11*R16 -> 7000000
B17: LTV | D17: % | E17: Rp. | F17: =100%-F16 -> 0.95 | G17: =F11-G16 -> 133000000 | I17: =100%-I16 -> 0.95 | J17: =I11-J16 -> 133000000 | L17: =100%-L16 -> 0.95 | M17: =L11-M16 -> 133000000 | O17: =100%-O16 -> 0.95 | P17: =O11-P16 -> 133000000 | R17: =100%-R16 -> 0.95 | S17: =R11-S16 -> 133000000
B18: RATE p.a (%) | D18: Eff R | E18: Flat Rate | F18: =VLOOKUP($I$7,Product!$B$6:$K$25,1+F9,0) -> 0.1374 | G18: =IF($D$6="ADDM",(((PMT(F18/12,G9,1,0,1)*(-1))*G9)-1)*12/G9,IF($D$6="ADDB",(((PMT(F18/12,G9,1,0,0)*(-1))*G9)-1)*12/G9," ")) -> 0.075977942 | H18: =G18+$S$5 -> 0.075977942 | I18: =VLOOKUP($I$7,Product!$B$6:$K$25,1+I9,0) -> 0.1345 | J18: =IF($D$6="ADDM",(((PMT(I18/12,J9,1,0,1)*(-1))*J9)-1)*12/J9,IF($D$6="ADDB",(((PMT(I18/12,J9,1,0,0)*(-1))*J9)-1)*12/J9," ")) -> 0.073041578 | K18: =J18+$S$5 -> 0.073041578 | L18: =VLOOKUP($I$7,Product!$B$6:$K$25,1+L9,0) -> 0.135 | M18: =IF($D$6="ADDM",(((PMT(L18/12,M9,1,0,1)*(-1))*M9)-1)*12/M9,IF($D$6="ADDB",(((PMT(L18/12,M9,1,0,0)*(-1))*M9)-1)*12/M9," ")) -> 0.073890115 | N18: =M18+$S$5 -> 0.073890115 | O18: =VLOOKUP($I$7,Product!$B$6:$K$25,1+O9,0) -> 0.1497 | P18: =IF($D$6="ADDM",(((PMT(O18/12,P9,1,0,1)*(-1))*P9)-1)*12/P9,IF($D$6="ADDB",(((PMT(O18/12,P9,1,0,0)*(-1))*P9)-1)*12/P9," ")) -> 0.083786521 | Q18: =P18+$S$5 -> 0.083786521 | R18: =VLOOKUP($I$7,Product!$B$6:$K$25,1+R9,0) -> 0.1589 | S18: =IF($D$6="ADDM",(((PMT(R18/12,S9,1,0,1)*(-1))*S9)-1)*12/S9,IF($D$6="ADDB",(((PMT(R18/12,S9,1,0,0)*(-1))*S9)-1)*12/S9," ")) -> 0.091115791 | T18: =S18+$S$5 -> 0.091115791
B19: Bunga Jual | D19: % | E19: Rp. | F19: =(H18*F9) -> 0.075977942 | G19: =G17*F19 -> 10105066 | I19: =(K18*I9) -> 0.14608316 | J19: =J17*I19 -> 19429060 | L19: =(N18*L9) -> 0.22167034 | M19: =M17*L19 -> 29482156 | O19: =(Q18*O9) -> 0.33514608 | P19: =P17*O19 -> 44574429 | R19: =(T18*R9) -> 0.45557895 | S19: =S17*R19 -> 60592001
B20: TOTAL A/R | G20: =G17+G19 -> 1.4310507e+08 | J20: =J17+J19 -> 1.5242906e+08 | M20: =M17+M19 -> 1.6248216e+08 | P20: =P17+P19 -> 1.7757443e+08 | S20: =S17+S19 -> 1.93592e+08
B21: ANGSURAN | F21: =ROUNDUP(G20/G9,-3) -> 11926000 | I21: =ROUNDUP(J20/J9,-3) -> 6352000 | L21: =ROUNDUP(M20/M9,-3) -> 4514000 | O21: =ROUNDUP(P20/P9,-3) -> 3700000 | R21: =ROUNDUP(S20/S9,-3) -> 3227000
B22: TOTAL BAYAR PERTAMA
B23: ASURANSI | F23: =IF(OR($I$8="Comprehensive 1 tahun, sisanya TLO",I8="Comprehensive All Tenor"),"Comprehensive","TLO") -> Comprehensive | I23: =IF($I$8="Comprehensive All Tenor","Comprehensive","TLO") -> TLO | L23: =IF($I$8="Comprehensive All Tenor","Comprehensive","TLO") -> TLO | O23: =IF($I$8="Comprehensive All Tenor","Comprehensive","TLO") -> TLO | R23: =IF($I$8="Comprehensive All Tenor","Comprehensive","TLO") -> TLO
C24: Casco | F24: =IF(F23="Comprehensive",IF(AND(G15>=1,G15<=125000000),'Asr Ext'!$C$22,IF(AND(G15>125000000,G15<=200000000),'Asr Ext'!$C$23,IF(AND(G15>200000000,G15<=400000000),'Asr Ext'!$C$24,IF(AND(G15>400000000,G15<=800000000),'Asr Ext'!$C$25,'Asr Ext'!$C$26)))),IF(AND(G15>=1,G15<=125000000),'Asr Ext'!$D$22,IF(AND(G15>125000000,G15<=200000000),'Asr Ext'!$D$23,IF(AND(G15>200000000,G15<=400000000),'Asr Ext'!$D$24,IF(AND(G15>400000000,G15<=800000000),'Asr Ext'!$D$25,'Asr Ext'!$D$26))))) -> 0.0247 | G24: =F24*G15 -> 3458000 | I24: =IF(I23="Comprehensive",IF(AND(J15>=1,J15<=125000000),'Asr Ext'!$C$22,IF(AND(J15>125000000,J15<=200000000),'Asr Ext'!$C$23,IF(AND(J15>200000000,J15<=400000000),'Asr Ext'!$C$24,IF(AND(J15>400000000,J15<=800000000),'Asr Ext'!$C$25,'Asr Ext'!$C$26)))),IF(AND(J15>=1,J15<=125000000),'Asr Ext'!$D$22,IF(AND(J15>125000000,J15<=200000000),'Asr Ext'!$D$23,IF(AND(J15>200000000,J15<=400000000),'Asr Ext'!$D$24,IF(AND(J15>400000000,J15<=800000000),'Asr Ext'!$D$25,'Asr Ext'!$D$26))))) -> 0.0044 | J24: =(I24*J15)+G24 -> 4012400 | L24: =IF(L23="Comprehensive",IF(AND(M15>=1,M15<=125000000),'Asr Ext'!$C$22,IF(AND(M15>125000000,M15<=200000000),'Asr Ext'!$C$23,IF(AND(M15>200000000,M15<=400000000),'Asr Ext'!$C$24,IF(AND(M15>400000000,M15<=800000000),'Asr Ext'!$C$25,'Asr Ext'!$C$26)))),IF(AND(M15>=1,M15<=125000000),'Asr Ext'!$D$22,IF(AND(M15>125000000,M15<=200000000),'Asr Ext'!$D$23,IF(AND(M15>200000000,M15<=400000000),'Asr Ext'!$D$24,IF(AND(M15>400000000,M15<=800000000),'Asr Ext'!$D$25,'Asr Ext'!$D$26))))) -> 0.0065 | M24: =(L24*M15)+J24 -> 4740400 | O24: =IF(O23="Comprehensive",IF(AND(P15>=1,P15<=125000000),'Asr Ext'!$C$22,IF(AND(P15>125000000,P15<=200000000),'Asr Ext'!$C$23,IF(AND(P15>200000000,P15<=400000000),'Asr Ext'!$C$24,IF(AND(P15>400000000,P15<=800000000),'Asr Ext'!$C$25,'Asr Ext'!$C$26)))),IF(AND(P15>=1,P15<=125000000),'Asr Ext'!$D$22,IF(AND(P15>125000000,P15<=200000000),'Asr Ext'!$D$23,IF(AND(P15>200000000,P15<=400000000),'Asr Ext'!$D$24,IF(AND(P15>400000000,P15<=800000000),'Asr Ext'!$D$25,'Asr Ext'!$D$26))))) -> 0.0065 | P24: =(O24*P15)+M24 -> 5377400 | R24: =IF(R23="Comprehensive",IF(AND(S15>=1,S15<=125000000),'Asr Ext'!$C$22,IF(AND(S15>125000000,S15<=200000000),'Asr Ext'!$C$23,IF(AND(S15>200000000,S15<=400000000),'Asr Ext'!$C$24,IF(AND(S15>400000000,S15<=800000000),'Asr Ext'!$C$25,'Asr Ext'!$C$26)))),IF(AND(S15>=1,S15<=125000000),'Asr Ext'!$D$22,IF(AND(S15>125000000,S15<=200000000),'Asr Ext'!$D$23,IF(AND(S15>200000000,S15<=400000000),'Asr Ext'!$D$24,IF(AND(S15>400000000,S15<=800000000),'Asr Ext'!$D$25,'Asr Ext'!$D$26))))) -> 0.0065 | S24: =(R24*S15)+P24 -> 6014400
C25: Loading | F25: =IFERROR(IF(F23="Comprehensive",VLOOKUP($D$8,'Asr Ext'!$L$6:$N$20,3,0),0),0) -> 0.05 | G25: =G24*F25 -> 172900 | I25: =IFERROR(IF(I23="Comprehensive",VLOOKUP($D$8,'Asr Ext'!$L$6:$N$20,3,0),0),0) -> 0 | J25: =(J24*I25)+G25 -> 172900 | L25: =IFERROR(IF(L23="Comprehensive",VLOOKUP($D$8,'Asr Ext'!$L$6:$N$20,3,0),0),0) -> 0 | M25: =(M24*L25)+J25 -> 172900 | O25: =IFERROR(IF(O23="Comprehensive",VLOOKUP($D$8,'Asr Ext'!$L$6:$N$20,3,0),0),0) -> 0 | P25: =(P24*O25)+M25 -> 172900 | R25: =IFERROR(IF(R23="Comprehensive",VLOOKUP($D$8,'Asr Ext'!$L$6:$N$20,3,0),0),0) -> 0 | S25: =(S24*R25)+P25 -> 172900
C26: Banjir | E26: Tidak | F26: =IF($E$26="YA",IF(F23="Comprehensive",0.1%,0%),0) -> 0 | G26: =F26*G15 -> 0 | I26: =IF($E$26="YA",IF(I23="Comprehensive",0.1%,0%),0) -> 0 | J26: =(I26*J15)+G26 -> 0 | L26: =IF($E$26="YA",IF(L23="Comprehensive",0.1%,0%),0) -> 0 | M26: =(L26*M15)+J26 -> 0 | O26: =IF($E$26="YA",IF(O23="Comprehensive",0.1%,0%),0) -> 0 | P26: =(O26*P15)+M26 -> 0 | R26: =IF($E$26="YA",IF(R23="Comprehensive",0.1%,0%),0) -> 0 | S26: =(R26*S15)+P26 -> 0
C27: Gempa | E27: Tidak | F27: =IF($E$27="YA",IF(F23="Comprehensive",0.1%,0%),0) -> 0 | G27: =F27*G15 -> 0 | I27: =IF($E$27="YA",IF(I23="Comprehensive",0.1%,0%),0) -> 0 | J27: =(I27*J15)+G27 -> 0 | L27: =IF($E$27="YA",IF(L23="Comprehensive",0.1%,0%),0) -> 0 | M27: =(L27*M15)+J27 -> 0 | O27: =IF($E$27="YA",IF(O23="Comprehensive",0.1%,0%),0) -> 0 | P27: =(O27*P15)+M27 -> 0 | R27: =IF($E$27="YA",IF(R23="Comprehensive",0.1%,0%),0) -> 0 | S27: =(R27*S15)+P27 -> 0
C28: Huru-hara | E28: Tidak | F28: =IF($E$28="YA",IF(F23="Comprehensive",0.05%,0%),0) -> 0 | G28: =F28*G15 -> 0 | I28: =IF($E$28="YA",IF(I23="Comprehensive",0.05%,0%),0) -> 0 | J28: =(I28*J15)+G28 -> 0 | L28: =IF($E$28="YA",IF(L23="Comprehensive",0.05%,0%),0) -> 0 | M28: =(L28*M15)+J28 -> 0 | O28: =IF($E$28="YA",IF(O23="Comprehensive",0.05%,0%),0) -> 0 | P28: =(O28*P15)+M28 -> 0 | R28: =IF($E$28="YA",IF(R23="Comprehensive",0.05%,0%),0) -> 0 | S28: =(R28*S15)+P28 -> 0
C29: Teroris | E29: Tidak | F29: =IF($E$29="YA",IF(F23="Comprehensive",0.05%,0%),0) -> 0 | G29: =F29*G15 -> 0 | I29: =IF($E$29="YA",IF(I23="Comprehensive",0.05%,0%),0) -> 0 | J29: =(I29*J15)+G29 -> 0 | L29: =IF($E$29="YA",IF(L23="Comprehensive",0.05%,0%),0) -> 0 | M29: =(L29*M15)+J29 -> 0 | O29: =IF($E$29="YA",IF(O23="Comprehensive",0.05%,0%),0) -> 0 | P29: =(O29*P15)+M29 -> 0 | R29: =IF($E$29="YA",IF(R23="Comprehensive",0.05%,0%),0) -> 0 | S29: =(R29*S15)+P29 -> 0
C30: ASURANSI CASCO + PERLUASAN | G30: =SUM(G24:H29) -> 3630900 | J30: =SUM(J24:K29) -> 4185300 | M30: =SUM(M24:N29) -> 4913300 | P30: =SUM(P24:Q29) -> 5550300 | S30: =SUM(S24:T29) -> 6187300
C31: GAP | E31: Tidak
C32: HIC | E32: Tidak
C33: TJH | D33: 0 | E33: Tidak | G33: =IF(F23="Comprehensive",VLOOKUP(F9,'Asr Ext'!$G$40:$M$44,7,0),0) -> 0 | J33: =IF(I23="Comprehensive",VLOOKUP(I9,'Asr Ext'!$G$40:$M$44,7,0),0)+G33 -> 0 | M33: =IF(L23="Comprehensive",VLOOKUP(L9,'Asr Ext'!$G$40:$M$44,7,0),0)+J33 -> 0 | P33: =IF(O23="Comprehensive",VLOOKUP(O9,'Asr Ext'!$G$40:$M$44,7,0),0)+M33 -> 0 | S33: =IF(R23="Comprehensive",VLOOKUP(R9,'Asr Ext'!$G$40:$M$44,7,0),0)+P33 -> 0
C34: Pengemudi | D34: 0 | E34: Tidak | F34: =IF($E$34="YA",IF(F23="Comprehensive",0.5%,0%),0) -> 0 | G34: =$D$34*F34 -> 0 | I34: =IF($E$34="YA",IF(I23="Comprehensive",0.5%,0%),0) -> 0 | J34: =(I34*$D$34)+G34 -> 0 | L34: =IF($E$34="YA",IF(L23="Comprehensive",0.5%,0%),0) -> 0 | M34: =(L34*$D$34)+J34 -> 0 | O34: =IF($E$34="YA",IF(O23="Comprehensive",0.5%,0%),0) -> 0 | P34: =(O34*$D$34)+M34 -> 0 | R34: =IF($E$34="YA",IF(R23="Comprehensive",0.5%,0%),0) -> 0 | S34: =(R34*$D$34)+P34 -> 0
C35: Penumpang | D35: 0 | E35: 0 | F35: =IF(AND(F23="Comprehensive",$E$35>0),0.1%,0%)*E35 -> 0 | G35: =F35*$D$35 -> 0 | I35: =IF(AND(I23="Comprehensive",$E$35>0),0.1%,0%)*H35 -> 0 | J35: =(I35*$D$35)+G35 -> 0 | L35: =IF(AND(L23="Comprehensive",$E$35>0),0.1%,0%)*K35 -> 0 | M35: =(L35*$D$35)+J35 -> 0 | O35: =IF(AND(O23="Comprehensive",$E$35>0),0.1%,0%)*N35 -> 0 | P35: =(O35*$D$35)+M35 -> 0 | R35: =IF(AND(R23="Comprehensive",$E$35>0),0.1%,0%)*Q35 -> 0 | S35: =(R35*$D$35)+P35 -> 0
C36: ACP | E36: =IF('Home Ext'!$I$9="Badan Hukum Usaha","Tidak","Ya") -> Ya | F36: =IF($E$36="Ya",IF(OR($I$6="Passenger",G17<1000000000),VLOOKUP($S$8,'Asr Ext'!$C$70:$H$73,F9+1,0),0),0) -> 0.0065 | G36: =F12*F36 -> 910000.1 | I36: =IF($E$36="Ya",IF(OR($I$6="Passenger",J17<1000000000),VLOOKUP($S$8,'Asr Ext'!$C$70:$H$73,I9+1,0),0),0) -> 0.013 | J36: =I12*I36 -> 1820000.2 | L36: =IF($E$36="Ya",IF(OR($I$6="Passenger",M17<1000000000),VLOOKUP($S$8,'Asr Ext'!$C$70:$H$73,L9+1,0),0),0) -> 0.01989 | M36: =L12*L36 -> 2784600.3 | O36: =IF($E$36="Ya",IF(OR($I$6="Passenger",P17<1000000000),VLOOKUP($S$8,'Asr Ext'!$C$70:$H$73,O9+1,0),0),0) -> 0.02912 | P36: =O12*O36 -> 4076800.5 | R36: =IF($E$36="Ya",IF(OR($I$6="Passenger",S17<1000000000),VLOOKUP($S$8,'Asr Ext'!$C$70:$H$73,R9+1,0),0),0) -> 0.03744 | S36: =R12*R36 -> 5241600.6
C37: GARANSI MESIN | E37: Ya | G37: =IF($E$37="ya",1500000,0) -> 1500000 | J37: =IF($E$37="ya",1500000,0) -> 1500000 | M37: =IF($E$37="ya",1500000,0) -> 1500000 | P37: =IF($E$37="ya",1500000,0) -> 1500000 | S37: =IF($E$37="ya",1500000,0) -> 1500000
B38: TOTAL ASURANSI | G38: =ROUNDDOWN(SUM(G31:H37)+G30,-2) -> 6040900 | J38: =ROUNDDOWN(SUM(J31:K37)+J30,-2) -> 7505300 | M38: =ROUNDDOWN(SUM(M31:N37)+M30,-2) -> 9197900 | P38: =ROUNDDOWN(SUM(P31:Q37)+P30,-2) -> 11127100 | S38: =ROUNDDOWN(SUM(S31:T37)+S30,-2) -> 12928900
B39: PROVISI | E39: =S7 -> 0 | F39: =VLOOKUP($I$7,Product!$B$6:$K$25,10,0)+$E$39 -> 0 | G39: =F39*G17 -> 0 | I39: =VLOOKUP($I$7,Product!$B$6:$K$25,10,0)+$E$39 -> 0 | J39: =I39*J17 -> 0 | L39: =VLOOKUP($I$7,Product!$B$6:$K$25,10,0)+$E$39 -> 0 | M39: =L39*M17 -> 0 | O39: =VLOOKUP($I$7,Product!$B$6:$K$25,10,0)+$E$39 -> 0 | P39: =O39*P17 -> 0 | R39: =VLOOKUP($I$7,Product!$B$6:$K$25,10,0)+$E$39 -> 0 | S39: =R39*S17 -> 0
B40: ADMINISTRASI | F40: =VLOOKUP($I$7,Product!$B$6:$K$25,9,0) -> 4400000 | I40: =VLOOKUP($I$7,Product!$B$6:$K$25,9,0) -> 4400000 | L40: =VLOOKUP($I$7,Product!$B$6:$K$25,9,0) -> 4400000 | O40: =VLOOKUP($I$7,Product!$B$6:$K$25,9,0) -> 4400000 | R40: =VLOOKUP($I$7,Product!$B$6:$K$25,9,0) -> 4400000
B41: FIDUCIA | F41: =IF(AND(F11>0,F11<=25000000),350000,IF(AND(F11>25000000,F11<=50000000),375000,IF(AND(F11>50000000,F11<=100000000),400000,IF(AND(F11>100000000,F11<=250000000),500000,IF(AND(F11>250000000,F11<=500000000),750000,IF(AND(F11>500000000,F11<=1000000000),1150000,2250000)))))) -> 500000 | I41: =IF(AND(I11>0,I11<=25000000),350000,IF(AND(I11>25000000,I11<=50000000),375000,IF(AND(I11>50000000,I11<=100000000),400000,IF(AND(I11>100000000,I11<=250000000),500000,IF(AND(I11>250000000,I11<=500000000),750000,IF(AND(I11>500000000,I11<=1000000000),1150000,2250000)))))) -> 500000 | L41: =IF(AND(L11>0,L11<=25000000),350000,IF(AND(L11>25000000,L11<=50000000),375000,IF(AND(L11>50000000,L11<=100000000),400000,IF(AND(L11>100000000,L11<=250000000),500000,IF(AND(L11>250000000,L11<=500000000),750000,IF(AND(L11>500000000,L11<=1000000000),1150000,2250000)))))) -> 500000 | O41: =IF(AND(O11>0,O11<=25000000),350000,IF(AND(O11>25000000,O11<=50000000),375000,IF(AND(O11>50000000,O11<=100000000),400000,IF(AND(O11>100000000,O11<=250000000),500000,IF(AND(O11>250000000,O11<=500000000),750000,IF(AND(O11>500000000,O11<=1000000000),1150000,2250000)))))) -> 500000 | R41: =IF(AND(R11>0,R11<=25000000),350000,IF(AND(R11>25000000,R11<=50000000),375000,IF(AND(R11>50000000,R11<=100000000),400000,IF(AND(R11>100000000,R11<=250000000),500000,IF(AND(R11>250000000,R11<=500000000),750000,IF(AND(R11>500000000,R11<=1000000000),1150000,2250000)))))) -> 500000
B42: ANGSURAN | F42: =IF($D$6="ADDM",11,12) -> 12 | G42: =ROUNDUP(IF($D$6="ADDM",G20/G9,0),-3) -> 0 | I42: =IF($D$6="ADDM",23,24) -> 24 | J42: =ROUNDUP(IF($D$6="ADDM",J20/J9,0),-3) -> 0 | L42: =IF($D$6="ADDM",35,36) -> 36 | M42: =ROUNDUP(IF($D$6="ADDM",M20/M9,0),-3) -> 0 | O42: =IF($D$6="ADDM",47,48) -> 48 | P42: =ROUNDUP(IF($D$6="ADDM",P20/P9,0),-3) -> 0 | R42: =IF($D$6="ADDM",59,60) -> 60 | S42: =ROUNDUP(IF($D$6="ADDM",S20/S9,0),-3) -> 0
B43: TOTAL BAYAR PERTAMA | F43: =G16+G38+G39+F40+F41 -> 17940900 | I43: =J16+J38+J39+I40+I41 -> 19405300 | L43: =M16+M38+M39+L40+L41 -> 21097900 | O43: =P16+P38+P39+O40+O41 -> 23027100 | R43: =S16+S38+S39+R40+R41 -> 24828900
...

Sheet UC Ext
B4: Merk | D4: ='Home Ext'!$O$21 -> HONDA | G4: Type Kendaraan | I4: ='Home Ext'!$O$25 -> BRIO | N4: Deposit Angsuran | P4: 0 | Q4: Up ACP | S4: 0
B5: Type Debitur | D5: ='Home Ext'!$O$9 -> Perorangan (Wiraswasta) | G5: Model Kendaraan | I5: ='Home Ext'!$O$29 -> ALL NEW BRIO RS CVT | N5: BBNKB | O5: 0 | Q5: Up Rate | S5: 0.005
B6: Type Angsuran | D6: ='Home Ext'!$Q$33 -> ADDB | G6: Penggunaan Unit | I6: ='Home Ext'!$O$17 -> Commercial | N6: PKB | O6: 0 | Q6: Up Adm | S6: 0
B7: Type Unit | D7: =VLOOKUP('Home Ext'!$O$21,'PHPM 2 UC Ext'!$D$4:$E$53,2,0) -> Japan | G7: Product | I7: =CONCATENATE("Captive"," ",'Home Ext'!$O$17," ","Low Rate") -> Captive Commercial Low Rate | N7: FAKTUR | O7: 0 | Q7: Up Provisi | S7: 0
B8: Thn (NIK) | D8: ='Home Ext'!$O$33 -> 2015 | F8: =15-(2026-D8) -> 4 | G8: Asuransi | I8: ='Home Ext'!$O$37 -> TLO All Tenor | N8: Asuransi | O8: BATAS BAWAH | Q8: Usia Debitur | S8: ='Home Ext'!$I$13 -> 36-45 tahun
B9: TENOR | F9: 1 | G9: =F9*12 -> 12 | I9: 2 | J9: =I9*12 -> 24 | L9: 3 | M9: =L9*12 -> 36 | O9: 4 | P9: =O9*12 -> 48 | R9: 5 | S9: =R9*12 -> 60
B10: =CONCATENATE('Home Ext'!$O$21,"-",'Home Ext'!$O$25,"-",'Home Ext'!$O$29) -> HONDA-BRIO-ALL NEW BRIO RS CVT | F10: =(16-F9)-(2026-$D$8) -> 4 | I10: =(16-I9)-(2026-$D$8) -> 3 | L10: =(16-L9)-(2026-$D$8) -> 2 | O10: =(16-O9)-(2026-$D$8) -> 1 | R10: =(16-R9)-(2026-$D$8) -> 0
B11: Harga OTR | D11: Showroom | F11: ='Home Ext'!$O$49 -> 110000000 | I11: ='Home Ext'!$O$49 -> 110000000 | L11: ='Home Ext'!$O$49 -> 110000000 | O11: ='Home Ext'!$O$49 -> 110000000 | R11: ='Home Ext'!$O$49 -> 110000000
D12: PHPM | F12: =IF(F10>=1,VLOOKUP($B$10,'PHPM 1 UC Ext'!$K$5:$L$841,2,0),0) -> #N/A | I12: =IF(I10>=1,VLOOKUP($B$10,'PHPM 1 DT Ext'!$K$5:$L$841,2,0),0) -> 140000016 | L12: =IF(L10>=1,VLOOKUP($B$10,'PHPM 1 DT Ext'!$K$5:$L$841,2,0),0) -> 140000016 | O12: =IF(O10>=1,VLOOKUP($B$10,'PHPM 1 DT Ext'!$K$5:$L$841,2,0),0) -> 140000016 | R12: =IF(R10>=1,VLOOKUP($B$10,'PHPM 1 DT Ext'!$K$5:$L$841,2,0),0) -> 0
D13: ROUNDDOWN PHPM | F13: =ROUNDDOWN(F12,-2) -> #N/A | I13: =ROUNDDOWN(I12,-2) -> 140000000 | L13: =ROUNDDOWN(L12,-2) -> 140000000 | O13: =ROUNDDOWN(O12,-2) -> 140000000 | R13: =ROUNDDOWN(R12,-2) -> 0
B14: Deviasi (%) | D14: (Rp.) | F14: =IFERROR(G14/F11,0) -> 0 | G14: =IF(F11<=F12,0,F11-F12) -> #N/A | I14: =IFERROR(J14/I11,0) -> 0 | J14: =IF(I11<=I12,0,I11-I12) -> 0 | L14: =IFERROR(M14/L11,0) -> 0 | M14: =IF(L11<=L12,0,L11-L12) -> 0 | O14: =IFERROR(P14/O11,0) -> 0 | P14: =IF(O11<=O12,0,O11-O12) -> 0 | R14: =IFERROR(S14/R11,0) -> 1 | S14: =IF(R11<=R12,0,R11-R12) -> 110000000
B15: Sum Insured | D15: % | E15: Rp. | F15: 1 | G15: =F11*F15 -> 110000000 | I15: 0.9 | J15: =I11*I15 -> 99000000 | L15: 0.8 | M15: =L11*L15 -> 88000000 | O15: 0.7 | P15: =O11*O15 -> 77000000 | R15: 0.7 | S15: =R11*R15 -> 77000000
B16: Net DP | D16: % | E16: Rp. | F16: =IF('Home Ext'!$O$9="Perorangan (Wiraswasta)",30%+F14,10%+F14) -> 0.3 | G16: =F11*F16 -> 33000000 | I16: =IF('Home Ext'!$O$9="Perorangan (Wiraswasta)",30%+I14,10%+I14) -> 0.3 | J16: =I11*I16 -> 33000000 | L16: =IF('Home Ext'!$O$9="Perorangan (Wiraswasta)",30%+L14,10%+L14) -> 0.3 | M16: =L11*L16 -> 33000000 | O16: =IF('Home Ext'!$O$9="Perorangan (Wiraswasta)",30%+O14,10%+O14) -> 0.3 | P16: =O11*O16 -> 33000000 | R16: =IF('Home Ext'!$O$9="Perorangan (Wiraswasta)",30%+R14,10%+R14) -> 1.3 | S16: =R11*R16 -> 143000000
B17: LTV | D17: % | E17: Rp. | F17: =100%-F16 -> 0.7 | G17: =F11-G16 -> 77000000 | I17: =100%-I16 -> 0.7 | J17: =I11-J16 -> 77000000 | L17: =100%-L16 -> 0.7 | M17: =L11-M16 -> 77000000 | O17: =100%-O16 -> 0.7 | P17: =O11-P16 -> 77000000 | R17: =100%-R16 -> -0.3 | S17: =R11-S16 -> -33000000
B18: RATE p.a (%) | D18: Eff R | E18: Flat Rate | F18: =VLOOKUP($I$7,Product!$B$6:$K$25,1+F9,0) -> #N/A | G18: =IF($D$6="ADDM",(((PMT(F18/12,G9,1,0,1)*(-1))*G9)-1)*12/G9,IF($D$6="ADDB",(((PMT(F18/12,G9,1,0,0)*(-1))*G9)-1)*12/G9," ")) -> #N/A | H18: =G18+$S$5 -> #N/A | I18: =VLOOKUP($I$7,Product!$B$6:$K$25,1+I9,0) -> #N/A | J18: =IF($D$6="ADDM",(((PMT(I18/12,J9,1,0,1)*(-1))*J9)-1)*12/J9,IF($D$6="ADDB",(((PMT(I18/12,J9,1,0,0)*(-1))*J9)-1)*12/J9," ")) -> #N/A | K18: =J18+$S$5 -> #N/A | L18: =VLOOKUP($I$7,Product!$B$6:$K$25,1+L9,0) -> #N/A | M18: =IF($D$6="ADDM",(((PMT(L18/12,M9,1,0,1)*(-1))*M9)-1)*12/M9,IF($D$6="ADDB",(((PMT(L18/12,M9,1,0,0)*(-1))*M9)-1)*12/M9," ")) -> #N/A | N18: =M18+$S$5 -> #N/A | O18: =VLOOKUP($I$7,Product!$B$6:$K$25,1+O9,0) -> #N/A | P18: =IF($D$6="ADDM",(((PMT(O18/12,P9,1,0,1)*(-1))*P9)-1)*12/P9,IF($D$6="ADDB",(((PMT(O18/12,P9,1,0,0)*(-1))*P9)-1)*12/P9," ")) -> #N/A | Q18: =P18+$S$5 -> #N/A | R18: =VLOOKUP($I$7,Product!$B$6:$K$25,1+R9,0) -> #N/A | S18: =IF($D$6="ADDM",(((PMT(R18/12,S9,1,0,1)*(-1))*S9)-1)*12/S9,IF($D$6="ADDB",(((PMT(R18/12,S9,1,0,0)*(-1))*S9)-1)*12/S9," ")) -> #N/A | T18: =S18+$S$5 -> #N/A
B19: Bunga Jual | D19: % | E19: Rp. | F19: =(H18*F9) -> #N/A | G19: =G17*F19 -> #N/A | I19: =(K18*I9) -> #N/A | J19: =J17*I19 -> #N/A | L19: =(N18*L9) -> #N/A | M19: =M17*L19 -> #N/A | O19: =(Q18*O9) -> #N/A | P19: =P17*O19 -> #N/A | R19: =(T18*R9) -> #N/A | S19: =S17*R19 -> #N/A
B20: TOTAL A/R | G20: =G17+G19 -> #N/A | J20: =J17+J19 -> #N/A | M20: =M17+M19 -> #N/A | P20: =P17+P19 -> #N/A | S20: =S17+S19 -> #N/A
B21: ANGSURAN | F21: =IF(F12=0,0,ROUNDUP(G20/G9,-3)) -> #N/A | I21: =IF(I12=0,0,ROUNDUP(J20/J9,-3)) -> #N/A | L21: =IF(L12=0,0,ROUNDUP(M20/M9,-3)) -> #N/A | O21: =IF(O12=0,0,ROUNDUP(P20/P9,-3)) -> #N/A | R21: =IF(R12=0,0,ROUNDUP(S20/S9,-3)) -> 0
B22: TOTAL BAYAR PERTAMA
B23: ASURANSI | F23: =IF(OR($I$8="Comprehensive 1 tahun",$I$8="Comprehensive All Tenor"),"Comprehensive","TLO") -> TLO | I23: =IF($I$8="Comprehensive All Tenor","Comprehensive","TLO") -> TLO | L23: =IF($I$8="Comprehensive All Tenor","Comprehensive","TLO") -> TLO | O23: =IF($I$8="Comprehensive All Tenor","Comprehensive","TLO") -> TLO | R23: =IF($I$8="Comprehensive All Tenor","Comprehensive","TLO") -> TLO
C24: Casco | F24: =IF(F23="Comprehensive",IF(AND(G15>=1,G15<=125000000),'Asr Ext'!$C$22,IF(AND(G15>125000000,G15<=200000000),'Asr Ext'!$C$23,IF(AND(G15>200000000,G15<=400000000),'Asr Ext'!$C$24,IF(AND(G15>400000000,G15<=800000000),'Asr Ext'!$C$25,'Asr Ext'!$C$26)))),IF(AND(G15>=1,G15<=125000000),'Asr Ext'!$D$22,IF(AND(G15>125000000,G15<=200000000),'Asr Ext'!$D$23,IF(AND(G15>200000000,G15<=400000000),'Asr Ext'!$D$24,IF(AND(G15>400000000,G15<=800000000),'Asr Ext'!$D$25,'Asr Ext'!$D$26))))) -> 0.0065 | G24: =F24*G15 -> 715000 | I24: =IF(I23="Comprehensive",IF(AND(J15>=1,J15<=125000000),'Asr Ext'!$C$22,IF(AND(J15>125000000,J15<=200000000),'Asr Ext'!$C$23,IF(AND(J15>200000000,J15<=400000000),'Asr Ext'!$C$24,IF(AND(J15>400000000,J15<=800000000),'Asr Ext'!$C$25,'Asr Ext'!$C$26)))),IF(AND(J15>=1,J15<=125000000),'Asr Ext'!$D$22,IF(AND(J15>125000000,J15<=200000000),'Asr Ext'!$D$23,IF(AND(J15>200000000,J15<=400000000),'Asr Ext'!$D$24,IF(AND(J15>400000000,J15<=800000000),'Asr Ext'!$D$25,'Asr Ext'!$D$26))))) -> 0.0065 | J24: =(I24*J15)+G24 -> 1358500 | L24: =IF(L23="Comprehensive",IF(AND(M15>=1,M15<=125000000),'Asr Ext'!$C$22,IF(AND(M15>125000000,M15<=200000000),'Asr Ext'!$C$23,IF(AND(M15>200000000,M15<=400000000),'Asr Ext'!$C$24,IF(AND(M15>400000000,M15<=800000000),'Asr Ext'!$C$25,'Asr Ext'!$C$26)))),IF(AND(M15>=1,M15<=125000000),'Asr Ext'!$D$22,IF(AND(M15>125000000,M15<=200000000),'Asr Ext'!$D$23,IF(AND(M15>200000000,M15<=400000000),'Asr Ext'!$D$24,IF(AND(M15>400000000,M15<=800000000),'Asr Ext'!$D$25,'Asr Ext'!$D$26))))) -> 0.0065 | M24: =(L24*M15)+J24 -> 1930500 | O24: =IF(O23="Comprehensive",IF(AND(P15>=1,P15<=125000000),'Asr Ext'!$C$22,IF(AND(P15>125000000,P15<=200000000),'Asr Ext'!$C$23,IF(AND(P15>200000000,P15<=400000000),'Asr Ext'!$C$24,IF(AND(P15>400000000,P15<=800000000),'Asr Ext'!$C$25,'Asr Ext'!$C$26)))),IF(AND(P15>=1,P15<=125000000),'Asr Ext'!$D$22,IF(AND(P15>125000000,P15<=200000000),'Asr Ext'!$D$23,IF(AND(P15>200000000,P15<=400000000),'Asr Ext'!$D$24,IF(AND(P15>400000000,P15<=800000000),'Asr Ext'!$D$25,'Asr Ext'!$D$26))))) -> 0.0065 | P24: =(O24*P15)+M24 -> 2431000 | R24: =IF(R23="Comprehensive",IF(AND(S15>=1,S15<=125000000),'Asr Ext'!$C$22,IF(AND(S15>125000000,S15<=200000000),'Asr Ext'!$C$23,IF(AND(S15>200000000,S15<=400000000),'Asr Ext'!$C$24,IF(AND(S15>400000000,S15<=800000000),'Asr Ext'!$C$25,'Asr Ext'!$C$26)))),IF(AND(S15>=1,S15<=125000000),'Asr Ext'!$D$22,IF(AND(S15>125000000,S15<=200000000),'Asr Ext'!$D$23,IF(AND(S15>200000000,S15<=400000000),'Asr Ext'!$D$24,IF(AND(S15>400000000,S15<=800000000),'Asr Ext'!$D$25,'Asr Ext'!$D$26))))) -> 0.0065 | S24: =(R24*S15)+P24 -> 2931500
C25: Loading | F25: =IFERROR(IF(F23="Comprehensive",VLOOKUP($D$8,'Asr Ext'!$L$6:$N$20,3,0),0),0) -> 0 | G25: =G24*F25 -> 0 | I25: =IFERROR(IF(I23="Comprehensive",VLOOKUP($D$8,'Asr Ext'!$L$6:$N$20,3,0),0),0) -> 0 | J25: =(J24*I25)+G25 -> 0 | L25: =IFERROR(IF(L23="Comprehensive",VLOOKUP($D$8,'Asr Ext'!$L$6:$N$20,3,0),0),0) -> 0 | M25: =(M24*L25)+J25 -> 0 | O25: =IFERROR(IF(O23="Comprehensive",VLOOKUP($D$8,'Asr Ext'!$L$6:$N$20,3,0),0),0) -> 0 | P25: =(P24*O25)+M25 -> 0 | R25: =IFERROR(IF(R23="Comprehensive",VLOOKUP($D$8,'Asr Ext'!$L$6:$N$20,3,0),0),0) -> 0 | S25: =(S24*R25)+P25 -> 0
C26: Banjir | E26: Tidak | F26: =IF($E$26="YA",IF(F23="Comprehensive",0.1%,0%),0) -> 0 | G26: =F26*G15 -> 0 | I26: =IF($E$26="YA",IF(I23="Comprehensive",0.1%,0%),0) -> 0 | J26: =(I26*J15)+G26 -> 0 | L26: =IF($E$26="YA",IF(L23="Comprehensive",0.1%,0%),0) -> 0 | M26: =(L26*M15)+J26 -> 0 | O26: =IF($E$26="YA",IF(O23="Comprehensive",0.1%,0%),0) -> 0 | P26: =(O26*P15)+M26 -> 0 | R26: =IF($E$26="YA",IF(R23="Comprehensive",0.1%,0%),0) -> 0 | S26: =(R26*S15)+P26 -> 0
C27: Gempa | E27: Tidak | F27: =IF($E$27="YA",IF(F23="Comprehensive",0.1%,0%),0) -> 0 | G27: =F27*G15 -> 0 | I27: =IF($E$27="YA",IF(I23="Comprehensive",0.1%,0%),0) -> 0 | J27: =(I27*J15)+G27 -> 0 | L27: =IF($E$27="YA",IF(L23="Comprehensive",0.1%,0%),0) -> 0 | M27: =(L27*M15)+J27 -> 0 | O27: =IF($E$27="YA",IF(O23="Comprehensive",0.1%,0%),0) -> 0 | P27: =(O27*P15)+M27 -> 0 | R27: =IF($E$27="YA",IF(R23="Comprehensive",0.1%,0%),0) -> 0 | S27: =(R27*S15)+P27 -> 0
C28: Huru-hara | E28: Tidak | F28: =IF($E$28="YA",IF(F23="Comprehensive",0.05%,0%),0) -> 0 | G28: =F28*G15 -> 0 | I28: =IF($E$28="YA",IF(I23="Comprehensive",0.05%,0%),0) -> 0 | J28: =(I28*J15)+G28 -> 0 | L28: =IF($E$28="YA",IF(L23="Comprehensive",0.05%,0%),0) -> 0 | M28: =(L28*M15)+J28 -> 0 | O28: =IF($E$28="YA",IF(O23="Comprehensive",0.05%,0%),0) -> 0 | P28: =(O28*P15)+M28 -> 0 | R28: =IF($E$28="YA",IF(R23="Comprehensive",0.05%,0%),0) -> 0 | S28: =(R28*S15)+P28 -> 0
C29: Teroris | E29: Tidak | F29: =IF($E$29="YA",IF(F23="Comprehensive",0.05%,0%),0) -> 0 | G29: =F29*G15 -> 0 | I29: =IF($E$29="YA",IF(I23="Comprehensive",0.05%,0%),0) -> 0 | J29: =(I29*J15)+G29 -> 0 | L29: =IF($E$29="YA",IF(L23="Comprehensive",0.05%,0%),0) -> 0 | M29: =(L29*M15)+J29 -> 0 | O29: =IF($E$29="YA",IF(O23="Comprehensive",0.05%,0%),0) -> 0 | P29: =(O29*P15)+M29 -> 0 | R29: =IF($E$29="YA",IF(R23="Comprehensive",0.05%,0%),0) -> 0 | S29: =(R29*S15)+P29 -> 0
C30: ASURANSI CASCO + PERLUASAN | F30: =SUM(G24:H29) -> 715000 | I30: =SUM(J24:K29) -> 1358500 | L30: =SUM(M24:N29) -> 1930500 | O30: =SUM(P24:Q29) -> 2431000 | R30: =SUM(S24:T29) -> 2931500
C31: GAP | E31: Tidak
C32: HIC | E32: Tidak
C33: TJH | D33: 0 | E33: Tidak | G33: =IF(F23="Comprehensive",VLOOKUP(F9,'Asr Ext'!$G$40:$M$44,7,0),0) -> 0 | J33: =IF(I23="Comprehensive",VLOOKUP(I9,'Asr Ext'!$G$40:$M$44,7,0),0)+G33 -> 0 | M33: =IF(L23="Comprehensive",VLOOKUP(L9,'Asr Ext'!$G$40:$M$44,7,0),0)+J33 -> 0 | P33: =IF(O23="Comprehensive",VLOOKUP(O9,'Asr Ext'!$G$40:$M$44,7,0),0)+M33 -> 0 | S33: =IF(R23="Comprehensive",VLOOKUP(R9,'Asr Ext'!$G$40:$M$44,7,0),0)+P33 -> 0
C34: Pengemudi | D34: 0 | E34: Tidak | F34: =IF($E$34="YA",IF(F23="Comprehensive",0.5%,0%),0) -> 0 | G34: =$D$34*F34 -> 0 | I34: =IF($E$34="YA",IF(I23="Comprehensive",0.5%,0%),0) -> 0 | J34: =(I34*$D$34)+G34 -> 0 | L34: =IF($E$34="YA",IF(L23="Comprehensive",0.5%,0%),0) -> 0 | M34: =(L34*$D$34)+J34 -> 0 | O34: =IF($E$34="YA",IF(O23="Comprehensive",0.5%,0%),0) -> 0 | P34: =(O34*$D$34)+M34 -> 0 | R34: =IF($E$34="YA",IF(R23="Comprehensive",0.5%,0%),0) -> 0 | S34: =(R34*$D$34)+P34 -> 0
C35: Penumpang | D35: 0 | E35: 0 | F35: =IF(AND(F23="Comprehensive",$E$35>0),0.1%,0%)*E35 -> 0 | G35: =F35*$D$35 -> 0 | I35: =IF(AND(I23="Comprehensive",$E$35>0),0.1%,0%)*H35 -> 0 | J35: =(I35*$D$35)+G35 -> 0 | L35: =IF(AND(L23="Comprehensive",$E$35>0),0.1%,0%)*K35 -> 0 | M35: =(L35*$D$35)+J35 -> 0 | O35: =IF(AND(O23="Comprehensive",$E$35>0),0.1%,0%)*N35 -> 0 | P35: =(O35*$D$35)+M35 -> 0 | R35: =IF(AND(R23="Comprehensive",$E$35>0),0.1%,0%)*Q35 -> 0 | S35: =(R35*$D$35)+P35 -> 0
C36: ACP | E36: Tidak | F36: =IF($E$36="Ya",IF(OR($I$6="Passenger",G17<1000000000),VLOOKUP($S$8,'Asr Ext'!$K$70:$P$73,F9+1,0),0),0) -> 0 | G36: =F11*F36 -> 0 | I36: =IF($E$36="Ya",IF(OR($I$6="Passenger",J17<1000000000),VLOOKUP($S$8,'Asr Ext'!$K$70:$P$73,I9+1,0),0),0) -> 0 | J36: =I11*I36 -> 0 | L36: =IF($E$36="Ya",IF(OR($I$6="Passenger",M17<1000000000),VLOOKUP($S$8,'Asr Ext'!$K$70:$P$73,L9+1,0),0),0) -> 0 | M36: =L11*L36 -> 0 | O36: =IF($E$36="Ya",IF(OR($I$6="Passenger",P17<1000000000),VLOOKUP($S$8,'Asr Ext'!$K$70:$P$73,O9+1,0),0),0) -> 0 | P36: =O11*O36 -> 0 | R36: =IF($E$36="Ya",IF(OR($I$6="Passenger",S17<1000000000),VLOOKUP($S$8,'Asr Ext'!$K$70:$P$73,R9+1,0),0),0) -> 0 | S36: =R11*R36 -> 0
C37: GARANSI MESIN | E37: Ya | G37: =IF($E$37="ya",1500000,0) -> 1500000 | J37: =IF($E$37="ya",1500000,0) -> 1500000 | M37: =IF($E$37="ya",1500000,0) -> 1500000 | P37: =IF($E$37="ya",1500000,0) -> 1500000 | S37: =IF($E$37="ya",1500000,0) -> 1500000
B38: TOTAL ASURANSI | F38: =ROUNDUP(SUM(G31:H37)+F30,-2) -> 2215000 | I38: =ROUNDUP(SUM(J31:K37)+I30,-2) -> 2858500 | L38: =ROUNDUP(SUM(M31:N37)+L30,-2) -> 3430500 | O38: =ROUNDUP(SUM(P31:Q37)+O30,-2) -> 3931000 | R38: =ROUNDUP(SUM(S31:T37)+R30,-2) -> 4431500
B39: PROVISI | E39: =S7 -> 0 | F39: =VLOOKUP($I$7,Product!$B$6:$K$25,10,0)+$E$39 -> #N/A | G39: =ROUNDUP(F39*G17,-2) -> #N/A | I39: =VLOOKUP($I$7,Product!$B$6:$K$25,10,0)+$E$39 -> #N/A | J39: =I39*J17 -> #N/A | L39: =VLOOKUP($I$7,Product!$B$6:$K$25,10,0)+$E$39 -> #N/A | M39: =L39*M17 -> #N/A | O39: =VLOOKUP($I$7,Product!$B$6:$K$25,10,0)+$E$39 -> #N/A | P39: =O39*P17 -> #N/A | R39: =VLOOKUP($I$7,Product!$B$6:$K$25,10,0)+$E$39 -> #N/A | S39: =R39*S17 -> #N/A
B40: ADMINISTRASI | F40: =VLOOKUP($I$7,Product!$B$6:$K$25,9,0) -> #N/A | I40: =VLOOKUP($I$7,Product!$B$6:$K$25,9,0) -> #N/A | L40: =VLOOKUP($I$7,Product!$B$6:$K$25,9,0) -> #N/A | O40: =VLOOKUP($I$7,Product!$B$6:$K$25,9,0) -> #N/A | R40: =VLOOKUP($I$7,Product!$B$6:$K$25,9,0) -> #N/A
B41: FIDUCIA | F41: =IF(AND(F11>0,F11<=25000000),350000,IF(AND(F11>25000000,F11<=50000000),375000,IF(AND(F11>50000000,F11<=100000000),400000,IF(AND(F11>100000000,F11<=250000000),500000,IF(AND(F11>250000000,F11<=500000000),750000,IF(AND(F11>500000000,F11<=1000000000),1150000,2250000)))))) -> 500000 | I41: =IF(AND(I11>0,I11<=25000000),350000,IF(AND(I11>25000000,I11<=50000000),375000,IF(AND(I11>50000000,I11<=100000000),400000,IF(AND(I11>100000000,I11<=250000000),500000,IF(AND(I11>250000000,I11<=500000000),750000,IF(AND(I11>500000000,I11<=1000000000),1150000,2250000)))))) -> 500000 | L41: =IF(AND(L11>0,L11<=25000000),350000,IF(AND(L11>25000000,L11<=50000000),375000,IF(AND(L11>50000000,L11<=100000000),400000,IF(AND(L11>100000000,L11<=250000000),500000,IF(AND(L11>250000000,L11<=500000000),750000,IF(AND(L11>500000000,L11<=1000000000),1150000,2250000)))))) -> 500000 | O41: =IF(AND(O11>0,O11<=25000000),350000,IF(AND(O11>25000000,O11<=50000000),375000,IF(AND(O11>50000000,O11<=100000000),400000,IF(AND(O11>100000000,O11<=250000000),500000,IF(AND(O11>250000000,O11<=500000000),750000,IF(AND(O11>500000000,O11<=1000000000),1150000,2250000)))))) -> 500000 | R41: =IF(AND(R11>0,R11<=25000000),350000,IF(AND(R11>25000000,R11<=50000000),375000,IF(AND(R11>50000000,R11<=100000000),400000,IF(AND(R11>100000000,R11<=250000000),500000,IF(AND(R11>250000000,R11<=500000000),750000,IF(AND(R11>500000000,R11<=1000000000),1150000,2250000)))))) -> 500000
B42: ANGSURAN PERTAMA | F42: =IF($D$6="ADDM",11,12) -> 12 | G42: =IF($D$6="ADDM",ROUNDUP(G20/G9,-3),0) -> 0 | I42: =IF($D$6="ADDM",23,24) -> 24 | J42: =IF($D$6="ADDM",ROUNDUP(J20/J9,-3),0) -> 0 | L42: =IF($D$6="ADDM",35,36) -> 36 | M42: =IF($D$6="ADDM",ROUNDUP(M20/M9,-3),0) -> 0 | O42: =IF($D$6="ADDM",47,48) -> 48 | P42: =IF($D$6="ADDM",ROUNDUP(P20/P9,-3),0) -> 0 | R42: =IF($D$6="ADDM",59,60) -> 60 | S42: =IF($D$6="ADDM",ROUNDUP(S20/S9,-3),0) -> 0
B43: TOTAL BAYAR PERTAMA | F43: =(G16+F38+G39+F40+F41+G42) -> #N/A | I43: =(J16+I38+J39+I40+I41+J42) -> #N/A | L43: =(M16+L38+M39+L40+L41+M42) -> #N/A | O43: =(P16+O38+P39+O40+O41+P42) -> #N/A | R43: =(S16+R38+S39+R40+R41+S42) -> #N/A
...

Sheet Asr Ext
C2: Wilayah 2
B3: OTR | C3: BATAS ATAS | G3: BATAS BAWAH | L3: LOADING ASURANSI
C4: Passenger | E4: Commercial | G4: Passenger | I4: Commercial
C5: Comprehensive | D5: TLO | E5: Comprehensive | F5: TLO | G5: Comprehensive | H5: TLO | I5: Comprehensive | J5: TLO
B6: 0-125 | C6: 0.0359 | D6: 0.0078 | E6: 0.0369 | F6: 0.0085 | G6: 0.0326 | H6: 0.0065 | I6: 0.0336 | J6: 0.0072 | L6: 2026 | M6: 0 | N6: 0 | O6: Comprehensive
B7: >125-200 | C7: 0.0272 | D7: 0.0053 | E7: 0.0282 | F7: 0.0057 | G7: 0.0247 | H7: 0.0044 | I7: 0.0257 | J7: 0.0048 | L7: =L6-1 -> 2025 | M7: 1 | N7: 0 | O7: Comprehensive
B8: >200-400 | C8: 0.0229 | D8: 0.0042 | E8: 0.0239 | F8: 0.0045 | G8: 0.0208 | H8: 0.0038 | I8: 0.0218 | J8: 0.0041 | L8: =L7-1 -> 2024 | M8: 2 | N8: 0 | O8: Comprehensive
B9: >400-800 | C9: 0.0132 | D9: 0.003 | E9: 0.0142 | F9: 0.0033 | G9: 0.012 | H9: 0.0025 | I9: 0.013 | J9: 0.0028 | L9: =L8-1 -> 2023 | M9: 3 | N9: 0 | O9: Comprehensive
B10: >800 | C10: 0.0116 | D10: 0.0024 | E10: 0.0126 | F10: 0.0026 | G10: 0.0105 | H10: 0.002 | I10: 0.0115 | J10: 0.0022 | L10: =L9-1 -> 2022 | M10: 4 | N10: 0 | O10: Comprehensive
L11: =L10-1 -> 2021 | M11: 5 | N11: 0 | O11: Comprehensive
B12: ='Home Ext'!$I$17 -> Passenger | C12: BATAS ATAS | E12: BATAS BAWAH | L12: =L11-1 -> 2020 | M12: 6 | N12: 0.05 | O12: Comprehensive Loading
C13: Comprehensive | D13: TLO | E13: Comprehensive | F13: TLO | L13: =L12-1 -> 2019 | M13: 7 | N13: 0.1 | O13: Comprehensive Loading
B14: 0-125 | C14: =IF($B$12="Passenger",C6,E6) -> 0.0359 | D14: =IF($B$12="Passenger",D6,F6) -> 0.0078 | E14: =IF($B$12="Passenger",G6,I6) -> 0.0326 | F14: =IF($B$12="Passenger",H6,J6) -> 0.0065 | L14: =L13-1 -> 2018 | M14: 8 | N14: 0.15 | O14: Comprehensive Loading
B15: >125-200 | C15: =IF($B$12="Passenger",C7,E7) -> 0.0272 | D15: =IF($B$12="Passenger",D7,F7) -> 0.0053 | E15: =IF($B$12="Passenger",G7,I7) -> 0.0247 | F15: =IF($B$12="Passenger",H7,J7) -> 0.0044 | L15: =L14-1 -> 2017 | M15: 9 | N15: 0.2 | O15: Comprehensive Loading
B16: >200-400 | C16: =IF($B$12="Passenger",C8,E8) -> 0.0229 | D16: =IF($B$12="Passenger",D8,F8) -> 0.0042 | E16: =IF($B$12="Passenger",G8,I8) -> 0.0208 | F16: =IF($B$12="Passenger",H8,J8) -> 0.0038 | L16: =L15-1 -> 2016 | M16: 10 | N16: 0.25 | O16: Comprehensive Loading
B17: >400-800 | C17: =IF($B$12="Passenger",C9,E9) -> 0.0132 | D17: =IF($B$12="Passenger",D9,F9) -> 0.003 | E17: =IF($B$12="Passenger",G9,I9) -> 0.012 | F17: =IF($B$12="Passenger",H9,J9) -> 0.0025 | L17: =L16-1 -> 2015 | M17: 11 | N17: 0
B18: >800 | C18: =IF($B$12="Passenger",C10,E10) -> 0.0116 | D18: =IF($B$12="Passenger",D10,F10) -> 0.0024 | E18: =IF($B$12="Passenger",G10,I10) -> 0.0105 | F18: =IF($B$12="Passenger",H10,J10) -> 0.002 | L18: =L17-1 -> 2014 | M18: 12 | N18: 0
L19: =L18-1 -> 2013 | M19: 13 | N19: 0
B20: =B12 -> Passenger | C20: ='DT Ext'!O8 -> BATAS BAWAH | L20: =L19-1 -> 2012 | M20: 14 | N20: 0
C21: Compre | D21: TLO
B22: 0-125 | C22: =IF($C$20="BATAS BAWAH",E14,C14) -> 0.0326 | D22: =IF($C$20="BATAS BAWAH",F14,D14) -> 0.0065
B23: >125-200 | C23: =IF($C$20="BATAS BAWAH",E15,C15) -> 0.0247 | D23: =IF($C$20="BATAS BAWAH",F15,D15) -> 0.0044
B24: >200-400 | C24: =IF($C$20="BATAS BAWAH",E16,C16) -> 0.0208 | D24: =IF($C$20="BATAS BAWAH",F16,D16) -> 0.0038
B25: >400-800 | C25: =IF($C$20="BATAS BAWAH",E17,C17) -> 0.012 | D25: =IF($C$20="BATAS BAWAH",F17,D17) -> 0.0025
B26: >800 | C26: =IF($C$20="BATAS BAWAH",E18,C18) -> 0.0105 | D26: =IF($C$20="BATAS BAWAH",F18,D18) -> 0.002
H28: TJH PEMBIAYAAN MOBIL BEKAS
B29: TENOR | C29: ACP BOTTOM | D29: UPPING | E29: ACP JUAL | H29: TJH NON KOMERSIAL | M29: TJH RUPIAH
B31: 12 | C31: =$D$70 -> 0.0065 | D31: =#REF! -> #REF! | E31: =C31+(C31*D31) -> #REF! | G31: 1 | H31: =IF('UC Ext'!$D$33>25000000,25000000,'UC Ext'!$D$33) -> 0 | I31: =IF('UC Ext'!$D$33>50000000,25000000,'UC Ext'!$D$33-H31) -> 0 | J31: =IF('UC Ext'!$D$33>50000000,25000000,'UC Ext'!$D$33-H31-I31) -> 0 | K31: ='UC Ext'!$D$33-H31-I31-J31 -> 0 | M31: =(H31*0.01)+(I31*0.005)+(J31*0.0025)+(K31*0.0015) -> 0
B32: 24 | C32: =$E$70 -> 0.013 | D32: =#REF! -> #REF! | E32: =C32+(C32*D32) -> #REF! | G32: 2 | H32: =IF('UC Ext'!$D$33>25000000,25000000,'UC Ext'!$D$33) -> 0 | I32: =IF('UC Ext'!$D$33>50000000,25000000,'UC Ext'!$D$33-H32) -> 0 | J32: =IF('UC Ext'!$D$33>50000000,25000000,'UC Ext'!$D$33-H32-I32) -> 0 | K32: ='UC Ext'!$D$33-H32-I32-J32 -> 0 | M32: =(H32*0.01)+(I32*0.005)+(J32*0.0025)+(K32*0.0015) -> 0
B33: 36 | C33: =$F$70 -> 0.01989 | D33: =#REF! -> #REF! | E33: =C33+(C33*D33) -> #REF! | G33: 3 | H33: =IF('UC Ext'!$D$33>25000000,25000000,'UC Ext'!$D$33) -> 0 | I33: =IF('UC Ext'!$D$33>50000000,25000000,'UC Ext'!$D$33-H33) -> 0 | J33: =IF('UC Ext'!$D$33>50000000,25000000,'UC Ext'!$D$33-H33-I33) -> 0 | K33: ='UC Ext'!$D$33-H33-I33-J33 -> 0 | M33: =(H33*0.01)+(I33*0.005)+(J33*0.0025)+(K33*0.0015) -> 0
B34: 48 | C34: =$G$70 -> 0.02912 | D34: =#REF! -> #REF! | E34: =C34+(C34*D34) -> #REF! | G34: 4 | H34: =IF('UC Ext'!$D$33>25000000,25000000,'UC Ext'!$D$33) -> 0 | I34: =IF('UC Ext'!$D$33>50000000,25000000,'UC Ext'!$D$33-H34) -> 0 | J34: =IF('UC Ext'!$D$33>50000000,25000000,'UC Ext'!$D$33-H34-I34) -> 0 | K34: ='UC Ext'!$D$33-H34-I34-J34 -> 0 | M34: =(H34*0.01)+(I34*0.005)+(J34*0.0025)+(K34*0.0015) -> 0
G35: 5 | H35: =IF('UC Ext'!$D$33>25000000,25000000,'UC Ext'!$D$33) -> 0 | I35: =IF('UC Ext'!$D$33>50000000,25000000,'UC Ext'!$D$33-H35) -> 0 | J35: =IF('UC Ext'!$D$33>50000000,25000000,'UC Ext'!$D$33-H35-I35) -> 0 | K35: ='UC Ext'!$D$33-H35-I35-J35 -> 0 | M35: =(H35*0.01)+(I35*0.005)+(J35*0.0025)+(K35*0.0015) -> 0 | X35: =IF(#REF!="COMPRE",1,0)+#REF! -> #REF! | Y35: =IF(#REF!="TLO",1,0)+#REF! -> #REF!
C37: RATE ACP BARU 2025 | H37: TJH DANA TUNAI
C38: 1 | D38: 2 | E38: 3 | F38: 4 | H38: TJH NON KOMERSIAL | M38: TJH RUPIAH
C39: 18-35th | D39: 36-45th | E39: 46-50th | F39: 51-60th
B40: 1 | C40: 0.005 | D40: 0.005 | E40: 0.005 | F40: 0.005 | G40: 1 | H40: =IF('DT Ext'!$D$33>25000000,25000000,'DT Ext'!$D$33) -> 0 | I40: =IF('DT Ext'!$D$33>50000000,25000000,'DT Ext'!$D$33-H40) -> 0 | J40: =IF('DT Ext'!$D$33>50000000,25000000,'DT Ext'!$D$33-H40-I40) -> 0 | K40: ='DT Ext'!$D$33-H40-I40-J40 -> 0 | M40: =(H40*0.01)+(I40*0.005)+(J40*0.0025)+(K40*0.0015) -> 0
B41: =B40+1 -> 2 | C41: 0.005 | D41: 0.005 | E41: 0.005 | F41: 0.005 | G41: 2 | H41: =IF('DT Ext'!D33>25000000,25000000,'DT Ext'!D33) -> 0 | I41: =IF('DT Ext'!$D$33>50000000,25000000,'DT Ext'!$D$33-H41) -> 0 | J41: =IF('DT Ext'!$D$33>50000000,25000000,'DT Ext'!$D$33-H41-I41) -> 0 | K41: ='DT Ext'!$D$33-H41-I41-J41 -> 0 | M41: =(H41*0.01)+(I41*0.005)+(J41*0.0025)+(K41*0.0015) -> 0
B42: =B41+1 -> 3 | C42: 0.0053 | D42: 0.0053 | E42: 0.0053 | F42: 0.0053 | G42: 3 | H42: =IF('DT Ext'!$D$33>25000000,25000000,'DT Ext'!$D$33) -> 0 | I42: =IF('DT Ext'!$D$33>50000000,25000000,'DT Ext'!$D$33-H42) -> 0 | J42: =IF('DT Ext'!$D$33>50000000,25000000,'DT Ext'!$D$33-H42-I42) -> 0 | K42: ='DT Ext'!$D$33-H42-I42-J42 -> 0 | M42: =(H42*0.01)+(I42*0.005)+(J42*0.0025)+(K42*0.0015) -> 0
B43: =B42+1 -> 4 | C43: 0.0071 | D43: 0.0071 | E43: 0.0071 | F43: 0.0071 | G43: 4 | H43: =IF('DT Ext'!$D$33>25000000,25000000,'DT Ext'!$D$33) -> 0 | I43: =IF('DT Ext'!$D$33>50000000,25000000,'DT Ext'!$D$33-H43) -> 0 | J43: =IF('DT Ext'!$D$33>50000000,25000000,'DT Ext'!$D$33-H43-I43) -> 0 | K43: ='DT Ext'!$D$33-H43-I43-J43 -> 0 | M43: =(H43*0.01)+(I43*0.005)+(J43*0.0025)+(K43*0.0015) -> 0
B44: =B43+1 -> 5 | C44: 0.0064 | D44: 0.0064 | E44: 0.0064 | F44: 0.0064 | G44: 5 | H44: =IF('DT Ext'!$D$33>25000000,25000000,'DT Ext'!$D$33) -> 0 | I44: =IF('DT Ext'!$D$33>50000000,25000000,'DT Ext'!$D$33-H44) -> 0 | J44: =IF('DT Ext'!$D$33>50000000,25000000,'DT Ext'!$D$33-H44-I44) -> 0 | K44: ='DT Ext'!$D$33-H44-I44-J44 -> 0 | M44: =(H44*0.01)+(I44*0.005)+(J44*0.0025)+(K44*0.0015) -> 0
...

Sheet Product
B3: 1 | C3: =B3+1 -> 2 | D3: =C3+1 -> 3 | E3: =D3+1 -> 4 | F3: =E3+1 -> 5 | G3: =F3+1 -> 6 | H3: =G3+1 -> 7 | I3: =H3+1 -> 8 | J3: =I3+1 -> 9 | K3: =J3+1 -> 10
A5: No | C5: 12 | D5: =C5+12 -> 24 | E5: =D5+12 -> 36 | F5: =E5+12 -> 48 | G5: =F5+12 -> 60 | H5: DP | I5: Admin Minimal | J5: Admin Maksimal | K5: Provisi
A6: 1 | B6: Captive Passenger Khusus Karyawan Bank Mandiri | C6: 0.1026 | D6: 0.0966 | E6: 0.0939 | F6: 0.0966 | G6: 0.1037 | H6: 0.05 | I6: 3500000 | J6: 4400000 | K6: 0
A7: 2 | B7: Captive Passenger Khusus SME & Private/Prioritas | C7: 0.1374 | D7: 0.1345 | E7: 0.135 | F7: 0.1497 | G7: 0.1589 | H7: 0.05 | I7: 3500000 | J7: 4400000 | K7: 0
A8: 3 | B8: Captive Passenger Semangat | C8: 0.1688 | D8: 0.1636 | E8: 0.1629 | F8: 0.1762 | G8: 0.1804 | H8: 0.05 | I8: 3500000 | J8: 4400000 | K8: 0
A9: 4 | B9: Captive Passenger Tengah | C9: 0.1769 | D9: 0.1685 | E9: 0.1697 | F9: 0.1784 | G9: 0.1865 | H9: 0.05 | I9: 3500000 | J9: 4400000 | K9: 0
A10: 5 | B10: Captive Passenger Cuan | C10: 0.1847 | D10: 0.1733 | E10: 0.1766 | F10: 0.1805 | G10: 0.1926 | H10: 0.05 | I10: 3500000 | J10: 4400000 | K10: 0
A11: 6 | B11: Captive Commercial Semangat | C11: 0.1983 | D11: 0.1907 | E11: 0.1931 | F11: 0.1921 | H11: 0.15 | I11: 3500000 | J11: 4400000 | K11: 0
A12: 7 | B12: Captive Commercial Tengah | C12: 0.2035 | D12: 0.1979 | E12: 0.1999 | F12: 0.1981 | H12: 0.15 | I12: 3500000 | J12: 4400000 | K12: 0
A13: 8 | B13: Captive Commercial Cuan | C13: 0.2088 | D13: 0.205 | E13: 0.2065 | F13: 0.2039 | H13: 0.15 | I13: 3500000 | J13: 4400000 | K13: 0
A14: 9 | B14: Reguler Passenger Referral | C14: 0.17253 | D14: 0.175 | E14: 0.18 | F14: 0.1869 | G14: 0.1907 | H14: 0.05 | I14: 3750000 | J14: 5350000 | K14: 0
A15: 10 | B15: Reguler Passenger TOMI Spesial Referral | C15: 0.1 | D15: 0.1025 | E15: 0.105 | F15: 0.1075 | G15: 0.11 | H15: 0.05 | I15: 3750000 | J15: 5350000 | K15: 0
A16: 11 | B16: Reguler Commercial Referral | C16: 0.2035 | D16: 0.1955 | E16: 0.1976 | F16: 0.1963 | H16: 0.15 | I16: 3750000 | J16: 5350000 | K16: 0
A17: 12 | B17: Reguler Passenger Sales Dealer | C17: 0.1847 | D17: 0.1733 | E17: 0.1766 | F17: 0.1805 | G17: 0.1926 | H17: 0.15 | I17: 3500000 | J17: 5350000 | K17: 0
A18: 13 | B18: Reguler Commercial Sales Dealer | C18: 0.2088 | D18: 0.205 | E18: 0.2065 | F18: 0.2039 | H18: 0.15 | I18: 3500000 | J18: 5350000 | K18: 0
A19: 14 | B19: Captive Passenger Authorized Showroom | C19: 0.14 | D19: 0.14 | E19: 0.14 | F19: 0.16 | G19: 0.16 | H19: 0.2 | I19: 4700000 | J19: 4700000 | K19: 0
A20: 15 | B20: Captive Passenger Low Rate | C20: 0.144699 | D20: 0.1468 | E20: 0.1455 | F20: 0.1623 | G20: 0.165 | H20: 0.1 | I20: 4700000 | J20: 4700000 | K20: 0
A21: 16 | B21: Captive Passenger Authorized Reguler | C21: 0.1622 | D21: 0.1643 | E21: 0.1624 | F21: 0.1751 | G21: 0.1766 | H21: 0.1 | I21: 4700000 | J21: 4700000 | K21: 0
A22: 17 | B22: Captive Passenger High Benefit | C22: 0.1797 | D22: 0.1816 | E22: 0.1792 | F22: 0.1943 | G22: 0.1918 | H22: 0.1 | I22: 4700000 | J22: 4700000 | K22: 0
A23: 18
A24: 19
A25: 20
B28: KONVERSI RATE
B29: ADDB | C29: =VLOOKUP($B$30,$B$6:$G$24,2,0) -> 0.1026 | D29: 0.12 | E29: =VLOOKUP($B$30,$B$6:$G$24,4,0) -> 0.0939 | F29: =VLOOKUP($B$30,$B$6:$G$24,5,0) -> 0.0966 | G29: =VLOOKUP($B$30,$B$6:$G$24,6,0) -> 0.1037
B30: Captive Passenger Khusus Karyawan Bank Mandiri | C30: =IF($B$29="ADDM",(((PMT($C$29/12,$C$5,1,0,1)*(-1))*$C$5)-1)*12/$C$5,IF($B$29="ADDB",(((PMT($C$29/12,$C$5,1,0,0)*(-1))*$C$5)-1)*12/$C$5," ")) -> 0.056442283 | D30: =IF($B$29="ADDM",(((PMT($D$29/12,$D$5,1,0,1)*(-1))*$D$5)-1)*12/$D$5,IF($B$29="ADDB",(((PMT($D$29/12,$D$5,1,0,0)*(-1))*$D$5)-1)*12/$D$5," ")) -> 0.064881667 | E30: =IF($B$29="ADDM",(((PMT($E$29/12,$E$5,1,0,1)*(-1))*$E$5)-1)*12/$E$5,IF($B$29="ADDB",(((PMT($E$29/12,$E$5,1,0,0)*(-1))*$E$5)-1)*12/$E$5," ")) -> 0.050445319 | F30: =IF($B$29="ADDM",(((PMT($F$29/12,$F$5,1,0,1)*(-1))*$F$5)-1)*12/$F$5,IF($B$29="ADDB",(((PMT($F$29/12,$F$5,1,0,0)*(-1))*$F$5)-1)*12/$F$5," ")) -> 0.052395351 | G30: =IF($B$29="ADDM",(((PMT($G$29/12,$G$5,1,0,1)*(-1))*$G$5)-1)*12/$G$5,IF($B$29="ADDB",(((PMT($G$29/12,$G$5,1,0,0)*(-1))*$G$5)-1)*12/$G$5," ")) -> 0.057154688

Sheet Data Ext
M2: REFERRAL | T2: Karyawan Perbankan | U2: Sales Dealer | V2: Karyawan Mandiri Cabang | W2: Karyawan Multifinance | X2: Karyawan Asuransi | Y2: Area Kyai Tapa | Z2: Area Daan Mogot | AA2: Area Green Ville | AC2: Graha Sultan
I3: ='Home Ext'!$C$91 -> Captive External | K3: ='Home Ext'!$C$93 -> SME & Private/Prioritas | M3: 1 | N3: 2 | O3: 3 | P3: 4 | Q3: 5 | R3: 6
C4: Referral | I4: =IF($I$3="Showroom Mobil Bekas",1,IF($I$3="Karyawan Internal",2,IF($I$3="Captive Internal",3,IF($I$3="Captive External",4,IF($I$3="Wira Agency Retail",5,IF($I$3="Wira Bisnis",6,0)))))) -> 4 | K4: =IF($K$3="Karyawan Perbankan",1,IF($K$3="Karyawan Authorized Dealer",2,IF($K$3="Karyawan Koperasi",3,IF($K$3="Karyawan Multifinance",4,IF($K$3="Karyawan Asuransi Rekanan",5,IF($K$3="Area Kyai Tapa",6,IF($K$3="Area Daan Mogot",7,IF($K$3="Area Green Ville",8,IF($K$3="Karyawan (Internal)",9,IF($K$3="Graha Sultan",10,0)))))))))) -> 0 | M4: Showroom Mobil Bekas | N4: Karyawan Internal | O4: Captive Internal | P4: Captive External | Q4: Wira Agency Retail | R4: Wira Bisnis | T4: 1 | U4: 2 | V4: 3 | W4: 4 | X4: 5 | Y4: 6 | Z4: 7 | AA4: 8 | AB4: 9 | AC4: 10
